Workbook

Sheet Summary
A1: NCF Chapter-wise Period Allocation — Summary
A2: Per-chapter periods = NCF annual total (ncf_period_norms.json) distributed across the grade's chapters by effort-index weight (largest-remainder), identical to the Aruvi API's ncf_estimated_periods. 40-minute periods. Generated 2026-07-08.
A4: Subject | B4: Grade | C4: Stage | D4: NCF annual periods | E4: Chapters in content | F4: Sum of chapter periods | G4: Min / chapter | H4: Max / chapter
A5: English | B5: III | C5: Preparatory | D5: ='Annual Budget'!E5 -> 270 | E5: 12 | F5: =SUM(English!D5:D16) -> 270 | G5: =MIN(English!D5:D16) -> 17 | H5: =MAX(English!D5:D16) -> 30
A6: English | B6: IV | C6: Preparatory | D6: ='Annual Budget'!E6 -> 270 | E6: 12 | F6: =SUM(English!D21:D32) -> 270 | G6: =MIN(English!D21:D32) -> 19 | H6: =MAX(English!D21:D32) -> 29
A7: English | B7: V | C7: Preparatory | D7: ='Annual Budget'!E7 -> 270 | E7: 10 | F7: =SUM(English!D37:D46) -> 270 | G7: =MIN(English!D37:D46) -> 22 | H7: =MAX(English!D37:D46) -> 34
A8: English | B8: VI | C8: Middle | D8: ='Annual Budget'!E8 -> 157 | E8: 16 | F8: =SUM(English!D51:D66) -> 157 | G8: =MIN(English!D51:D66) -> 4 | H8: =MAX(English!D51:D66) -> 14
A9: English | B9: VII | C9: Middle | D9: ='Annual Budget'!E9 -> 157 | E9: 15 | F9: =SUM(English!D71:D85) -> 157 | G9: =MIN(English!D71:D85) -> 6 | H9: =MAX(English!D71:D85) -> 14
A10: English | B10: VIII | C10: Middle | D10: ='Annual Budget'!E10 -> 157 | E10: 15 | F10: =SUM(English!D90:D104) -> 157 | G10: =MIN(English!D90:D104) -> 9 | H10: =MAX(English!D90:D104) -> 12
A11: English | B11: IX | C11: Secondary | D11: ='Annual Budget'!E11 -> 126 | E11: 8 | F11: =SUM(English!D109:D116) -> 126 | G11: =MIN(English!D109:D116) -> 12 | H11: =MAX(English!D109:D116) -> 19
A12: Mathematics | B12: III | C12: Preparatory | D12: ='Annual Budget'!E12 -> 277 | E12: 14 | F12: =SUM(Mathematics!D5:D18) -> 277 | G12: =MIN(Mathematics!D5:D18) -> 11 | H12: =MAX(Mathematics!D5:D18) -> 25
A13: Mathematics | B13: IV | C13: Preparatory | D13: ='Annual Budget'!E13 -> 277 | E13: 14 | F13: =SUM(Mathematics!D23:D36) -> 277 | G13: =MIN(Mathematics!D23:D36) -> 11 | H13: =MAX(Mathematics!D23:D36) -> 27
A14: Mathematics | B14: V | C14: Preparatory | D14: ='Annual Budget'!E14 -> 277 | E14: 15 | F14: =SUM(Mathematics!D41:D55) -> 277 | G14: =MIN(Mathematics!D41:D55) -> 13 | H14: =MAX(Mathematics!D41:D55) -> 29
A15: Mathematics | B15: VI | C15: Middle | D15: ='Annual Budget'!E15 -> 172 | E15: 10 | F15: =SUM(Mathematics!D60:D69) -> 172 | G15: =MIN(Mathematics!D60:D69) -> 8 | H15: =MAX(Mathematics!D60:D69) -> 23
A16: Mathematics | B16: VII | C16: Middle | D16: ='Annual Budget'!E16 -> 172 | E16: 8 | F16: =SUM(Mathematics!D74:D81) -> 172 | G16: =MIN(Mathematics!D74:D81) -> 18 | H16: =MAX(Mathematics!D74:D81) -> 31
A17: Mathematics | B17: VIII | C17: Middle | D17: ='Annual Budget'!E17 -> 172 | E17: 14 | F17: =SUM(Mathematics!D86:D99) -> 172 | G17: =MIN(Mathematics!D86:D99) -> 5 | H17: =MAX(Mathematics!D86:D99) -> 17
A18: Mathematics | B18: IX | C18: Secondary | D18: ='Annual Budget'!E18 -> 162 | E18: 16 | F18: =SUM(Mathematics!D104:D119) -> 162 | G18: =MIN(Mathematics!D104:D119) -> 8 | H18: =MAX(Mathematics!D104:D119) -> 15 | I18: Yes | J18: 9-16 dummy mapping
A19: Science | B19: VI | C19: Middle | D19: ='Annual Budget'!E19 -> 240 | E19: 12 | F19: =SUM(Science!D5:D16) -> 240 | G19: =MIN(Science!D5:D16) -> 5 | H19: =MAX(Science!D5:D16) -> 28
A20: Science | B20: VII | C20: Middle | D20: ='Annual Budget'!E20 -> 240 | E20: 12 | F20: =SUM(Science!D21:D32) -> 240 | G20: =MIN(Science!D21:D32) -> 10 | H20: =MAX(Science!D21:D32) -> 26
A21: Science | B21: VIII | C21: Middle | D21: ='Annual Budget'!E21 -> 240 | E21: 13 | F21: =SUM(Science!D37:D49) -> 240 | G21: =MIN(Science!D37:D49) -> 8 | H21: =MAX(Science!D37:D49) -> 24
A22: Science | B22: IX | C22: Secondary | D22: ='Annual Budget'!E22 -> 162 | E22: 13 | F22: =SUM(Science!D54:D66) -> 162 | G22: =MIN(Science!D54:D66) -> 5 | H22: =MAX(Science!D54:D66) -> 17
A23: Social Sciences | B23: VI | C23: Middle | D23: ='Annual Budget'!E23 -> 240 | E23: 14 | F23: =SUM('Social Sciences'!D5:D18) -> 240 | G23: =MIN('Social Sciences'!D5:D18) -> 11 | H23: =MAX('Social Sciences'!D5:D18) -> 27
A24: Social Sciences | B24: VII | C24: Middle | D24: ='Annual Budget'!E24 -> 240 | E24: 12 | F24: =SUM('Social Sciences'!D23:D34) -> 240 | G24: =MIN('Social Sciences'!D23:D34) -> 11 | H24: =MAX('Social Sciences'!D23:D34) -> 24
A25: Social Sciences | B25: VIII | C25: Middle | D25: ='Annual Budget'!E25 -> 240 | E25: 14 | F25: =SUM('Social Sciences'!D39:D52) -> 240 | G25: =MIN('Social Sciences'!D39:D52) -> 13 | H25: =MAX('Social Sciences'!D39:D52) -> 24 | I25: Yes | J25: 8-14 dummy mapping
A26: The World Around Us | B26: III | C26: Preparatory | D26: ='Annual Budget'!E26 -> 300 | E26: 12 | F26: =SUM('The World Around Us'!D5:D16) -> 300 | G26: =MIN('The World Around Us'!D5:D16) -> 13 | H26: =MAX('The World Around Us'!D5:D16) -> 35
A27: The World Around Us | B27: IV | C27: Preparatory | D27: ='Annual Budget'!E27 -> 300 | E27: 10 | F27: =SUM('The World Around Us'!D21:D30) -> 300 | G27: =MIN('The World Around Us'!D21:D30) -> 22 | H27: =MAX('The World Around Us'!D21:D30) -> 40
A28: The World Around Us | B28: V | C28: Preparatory | D28: ='Annual Budget'!E28 -> 300 | E28: 10 | F28: =SUM('The World Around Us'!D35:D44) -> 300 | G28: =MIN('The World Around Us'!D35:D44) -> 17 | H28: =MAX('The World Around Us'!D35:D44) -> 41
A30: Note: periods are distributed across chapters currently present in data/content, INCLUDING dummy placeholder chapters (Social Sciences VIII ch 8-14, Mathematics IX ch 9-16) that carry the average effort/weight of that grade's real chapters. These simulate the effect on period allocation of chapters NCERT has yet to publish; the annual total is redistributed across the full set, so each real chapter's share shrinks accordingly. Replace the dummies with real mappings on release.

Sheet Annual Budget
A1: Annual Budget — Source Values
A2: Single source of truth for each subject·grade annual teaching budget (40-min periods). Column D holds the recommended NCF value (from ncf_period_norms.json); column E is the Annual budget used everywhere else — it derives from D by formula, so it currently equals the NCF recommendation but can be overridden per grade to model a different budget. The Summary sheet and every detail sheet's block header link to column E.
A4: Subject | B4: Grade | C4: Stage | D4: Recommended NCF Periods | E4: Annual budget (periods)
A5: English | B5: III | C5: Preparatory | D5: 270 | E5: =D5 -> 270
A6: English | B6: IV | C6: Preparatory | D6: 270 | E6: =D6 -> 270
A7: English | B7: V | C7: Preparatory | D7: 270 | E7: =D7 -> 270
A8: English | B8: VI | C8: Middle | D8: 157 | E8: =D8 -> 157
A9: English | B9: VII | C9: Middle | D9: 157 | E9: =D9 -> 157
A10: English | B10: VIII | C10: Middle | D10: 157 | E10: =D10 -> 157
A11: English | B11: IX | C11: Secondary | D11: 126 | E11: =D11 -> 126
A12: Mathematics | B12: III | C12: Preparatory | D12: 277 | E12: =D12 -> 277
A13: Mathematics | B13: IV | C13: Preparatory | D13: 277 | E13: =D13 -> 277
A14: Mathematics | B14: V | C14: Preparatory | D14: 277 | E14: =D14 -> 277
A15: Mathematics | B15: VI | C15: Middle | D15: 172 | E15: =D15 -> 172
A16: Mathematics | B16: VII | C16: Middle | D16: 172 | E16: =D16 -> 172
... A28: The World Around Us | B28: V | C28: Preparatory | D28: 300 | E28: =D28 -> 300

Sheet English
A1: English — chapter-wise NCF period allocation
A3: ="Grade III (stage: preparatory, NCF annual total: "&'Annual Budget'!$E$5&" periods)" -> Grade III (stage: preparatory, NCF annual total: 270 periods)
A4: Ch # | B4: Chapter title | C4: Weight | D4: NCF periods
A5: 1 | B5: Fun with Friends | C5: 6.5 | D5: 17
A6: 2 | B6: Badal and Moti | C6: 11.5 | D6: 30
A7: 3 | B7: Best Friends | C7: 8 | D7: 21
A8: 4 | B8: Toys and Games | C8: 6.5 | D8: 17
A9: 5 | B9: Talking Toys | C9: 10 | D9: 26
A10: 6 | B10: Paper Boats | C10: 8.5 | D10: 22
A11: 7 | B11: The Big Laddoo | C11: 9.5 | D11: 24
A12: 8 | B12: Thank God! | C12: 8.5 | D12: 22
A13: 9 | B13: Madhu's Wish | C13: 10 | D13: 26
A14: 10 | B14: Night | C14: 6.5 | D14: 17
A15: 11 | B15: Chanda Mama Counts the Stars | C15: 8.5 | D15: 22
A16: 12 | B16: Chandrayaan | C16: 10 | D16: 26
B17: Total | C17: =SUM(C5:C16) -> 104 | D17: =SUM(D5:D16) -> 270
A19: ="Grade IV (stage: preparatory, NCF annual total: "&'Annual Budget'!$E$6&" periods)" -> Grade IV (stage: preparatory, NCF annual total: 270 periods)
A20: Ch # | B20: Chapter title | C20: Weight | D20: NCF periods
A21: 1 | B21: Together We Can | C21: 10 | D21: 23
A22: 2 | B22: The Tinkling Bells | C22: 11.5 | D22: 26
A23: 3 | B23: Be Smart, Be Safe | C23: 9.5 | D23: 21
A24: 4 | B24: One Thing at a Time | C24: 8.5 | D24: 19
A25: 5 | B25: The Old Stag | C25: 8.5 | D25: 19
A26: 6 | B26: Braille | C26: 10 | D26: 22
A27: 7 | B27: Fit Body, Fit Mind, Fit Nation | C27: 10 | D27: 22
A28: 8 | B28: The Lagori Champions | C28: 13 | D28: 29
A29: 9 | B29: Hekko | C29: 8.5 | D29: 19
A30: 10 | B30: The Swing | C30: 10 | D30: 22
A31: 11 | B31: A Journey to the Magical Mountains | C31: 13 | D31: 29
A32: 12 | B32: Maheshwar | C32: 8.5 | D32: 19
B33: Total | C33: =SUM(C21:C32) -> 121 | D33: =SUM(D21:D32) -> 270
A35: ="Grade V (stage: preparatory, NCF annual total: "&'Annual Budget'!$E$7&" periods)" -> Grade V (stage: preparatory, NCF annual total: 270 periods)
A36: Ch # | B36: Chapter title | C36: Weight | D36: NCF periods
A37: 1 | B37: Papa's Spectacles | C37: 8.5 | D37: 23
A38: 2 | B38: Gone with the Scooter | C38: 11.5 | D38: 30
A39: 3 | B39: The Rainbow | C39: 11.5 | D39: 30
A40: 4 | B40: The Wise Parrot | C40: 8.5 | D40: 23
A41: 5 | B41: The Frog | C41: 8.5 | D41: 22
A42: 6 | B42: What a Tank! | C42: 10 | D42: 26
A43: 7 | B43: Gilli Danda | C43: 13 | D43: 34
...

Sheet Mathematics
A1: Mathematics — chapter-wise NCF period allocation
A3: ="Grade III (stage: preparatory, NCF annual total: "&'Annual Budget'!$E$12&" periods)" -> Grade III (stage: preparatory, NCF annual total: 277 periods)
A4: Ch # | B4: Chapter title | C4: Weight | D4: NCF periods
A5: 1 | B5: What's in a Name? | C5: 6 | D5: 11
A6: 2 | B6: Toy Joy | C6: 7.5 | D6: 14
A7: 3 | B7: Double Century | C7: 13 | D7: 25
A8: 4 | B8: Vacation with My Nani Maa | C8: 9.5 | D8: 18
A9: 5 | B9: Fun with Shapes | C9: 13 | D9: 25
A10: 6 | B10: House of Hundreds - I | C10: 11.5 | D10: 22
A11: 7 | B11: Raksha Bandhan | C11: 13 | D11: 24
A12: 8 | B12: Fair Share | C12: 9.5 | D12: 18
A13: 9 | B13: House of Hundreds - II | C13: 11.5 | D13: 22
A14: 10 | B14: Fun at Class Party! | C14: 13 | D14: 24
A15: 11 | B15: Filling and Lifting | C15: 9.5 | D15: 18
A16: 12 | B16: Give and Take | C16: 7.5 | D16: 14
... A18: 14 | B18: The Surajkund Fair | C18: 9.5 | D18: 18
B19: Total | C19: =SUM(C5:C18) -> 147 | D19: =SUM(D5:D18) -> 277
A21: ="Grade IV (stage: preparatory, NCF annual total: "&'Annual Budget'!$E$13&" periods)" -> Grade IV (stage: preparatory, NCF annual total: 277 periods)
A22: Ch # | B22: Chapter title | C22: Weight | D22: NCF periods
A23: 1 | B23: Shapes Around Us | C23: 13 | D23: 23
A24: 2 | B24: Hide and Seek | C24: 6 | D24: 11
A25: 3 | B25: Patterns Around Us | C25: 9.5 | D25: 17
A26: 4 | B26: Thousands Around Us | C26: 11.5 | D26: 21
A27: 5 | B27: Sharing and Measuring | C27: 13 | D27: 23
A28: 6 | B28: Measuring Length | C28: 11 | D28: 20
A29: 7 | B29: The Cleanest Village | C29: 13 | D29: 23
A30: 8 | B30: Weigh It, Pour It | C30: 11.5 | D30: 21
A31: 9 | B31: Equal Groups | C31: 15 | D31: 27
A32: 10 | B32: Elephants, Tigers, and Leopards | C32: 11.5 | D32: 21
A33: 11 | B33: Fun with Symmetry | C33: 9.5 | D33: 17
A34: 12 | B34: Ticking Clocks and Turning Calendar | C34: 7.5 | D34: 13
... A36: 14 | B36: Data Handling | C36: 7.5 | D36: 13
B37: Total | C37: =SUM(C23:C36) -> 154.5 | D37: =SUM(D23:D36) -> 277
A39: ="Grade V (stage: preparatory, NCF annual total: "&'Annual Budget'!$E$14&" periods)" -> Grade V (stage: preparatory, NCF annual total: 277 periods)
A40: Ch # | B40: Chapter title | C40: Weight | D40: NCF periods
A41: 1 | B41: We the Travellers—I | C41: 9.5 | D41: 16
A42: 2 | B42: Fractions | C42: 7.5 | D42: 13
A43: 3 | B43: Angles as Turns | C43: 11 | D43: 19
A44: 4 | B44: We the Travellers — II | C44: 13 | D44: 23
A45: 5 | B45: Far and Near | C45: 16.5 | D45: 29
...

Sheet Science
A1: Science — chapter-wise NCF period allocation
A3: ="Grade VI (stage: middle, NCF annual total: "&'Annual Budget'!$E$19&" periods)" -> Grade VI (stage: middle, NCF annual total: 240 periods)
A4: Ch # | B4: Chapter title | C4: Weight | D4: NCF periods
A5: 1 | B5: The Wonderful World of Science | C5: 2 | D5: 5
A6: 2 | B6: Diversity in the Living World | C6: 12 | D6: 28
A7: 3 | B7: Mindful Eating: A Path to a Healthy Body | C7: 9.5 | D7: 22
A8: 4 | B8: Exploring Magnets | C8: 8 | D8: 18
A9: 5 | B9: Measurement of Length and Motion | C9: 8 | D9: 18
A10: 6 | B10: Materials Around Us | C10: 8 | D10: 18
A11: 7 | B11: Temperature and its Measurement | C11: 7.5 | D11: 17
A12: 8 | B12: A Journey through States of Water | C12: 12 | D12: 28
A13: 9 | B13: Methods of Separation in Everyday Life | C13: 11.5 | D13: 27
A14: 10 | B14: Living Creatures: Exploring their Characteristics | C14: 10 | D14: 23
A15: 11 | B15: Nature's Treasures | C15: 8 | D15: 18
A16: 12 | B16: Beyond Earth | C16: 8 | D16: 18
B17: Total | C17: =SUM(C5:C16) -> 104.5 | D17: =SUM(D5:D16) -> 240
A19: ="Grade VII (stage: middle, NCF annual total: "&'Annual Budget'!$E$20&" periods)" -> Grade VII (stage: middle, NCF annual total: 240 periods)
A20: Ch # | B20: Chapter title | C20: Weight | D20: NCF periods
A21: 1 | B21: The Ever-Evolving World of Science | C21: 4 | D21: 10
A22: 2 | B22: Exploring Substances: Acidic, Basic, and Neutral | C22: 8 | D22: 19
A23: 3 | B23: Electricity — Circuits and their Components | C23: 10 | D23: 24
A24: 4 | B24: The World of Metals and Non-metals | C24: 9.5 | D24: 23
A25: 5 | B25: Changes Around Us — Physical and Chemical | C25: 8 | D25: 19
A26: 6 | B26: Adolescence — A Stage of Growth and Change | C26: 6 | D26: 15
A27: 7 | B27: Heat Transfer in Nature | C27: 8 | D27: 19
A28: 8 | B28: Measurement of Time and Motion | C28: 8 | D28: 19
A29: 9 | B29: Life Processes in Animals | C29: 9.5 | D29: 23
A30: 10 | B30: Life Processes in Plants | C30: 11 | D30: 26
A31: 11 | B31: Light — Shadows and Reflections | C31: 10 | D31: 24
A32: 12 | B32: Earth, Moon, and the Sun | C32: 8 | D32: 19
B33: Total | C33: =SUM(C21:C32) -> 100 | D33: =SUM(D21:D32) -> 240
A35: ="Grade VIII (stage: middle, NCF annual total: "&'Annual Budget'!$E$21&" periods)" -> Grade VIII (stage: middle, NCF annual total: 240 periods)
A36: Ch # | B36: Chapter title | C36: Weight | D36: NCF periods
A37: 1 | B37: Exploring the Investigative World of Science | C37: 4 | D37: 8
A38: 2 | B38: The Invisible Living World: Beyond Our Naked Eye | C38: 11.5 | D38: 23
A39: 3 | B39: Health: The Ultimate Treasure | C39: 6 | D39: 12
A40: 4 | B40: Electricity: Magnetic and Heating Effects | C40: 10 | D40: 20
A41: 5 | B41: Exploring Forces | C41: 12 | D41: 24
A42: 6 | B42: Pressure, Winds, Storms, and Cyclones | C42: 8 | D42: 16
A43: 7 | B43: Particulate Nature of Matter | C43: 12 | D43: 23
...

Sheet Social Sciences
A1: Social Sciences — chapter-wise NCF period allocation
A3: ="Grade VI (stage: middle, NCF annual total: "&'Annual Budget'!$E$23&" periods)" -> Grade VI (stage: middle, NCF annual total: 240 periods)
A4: Ch # | B4: Chapter title | C4: Weight | D4: NCF periods
A5: 1 | B5: Chapter 1: Locating Places on the Earth | C5: 5 | D5: 11
A6: 2 | B6: Chapter 02: Oceans and Continents | C6: 8 | D6: 17
A7: 3 | B7: Chapter 3: Landforms and Life | C7: 9 | D7: 19
A8: 4 | B8: Chapter 4: Timeline and Sources of History | C8: 8 | D8: 17
A9: 5 | B9: Chapter 5: India, That Is Bharat | C9: 7 | D9: 15
A10: 6 | B10: Chapter 6: The Beginnings of Indian Civilisation | C10: 13 | D10: 27
A11: 7 | B11: Chapter 7: India's Cultural Roots | C11: 12 | D11: 25
A12: 8 | B12: Chapter 8: Unity in Diversity, or 'Many in the One' | C12: 7 | D12: 15
A13: 9 | B13: Chapter 9: Family and Community | C13: 8 | D13: 17
A14: 10 | B14: Chapter 10: Grassroots Democracy – Part 1 Governance | C14: 8 | D14: 17
A15: 11 | B15: Chapter 11: Grassroots Democracy – Part 2: Local Government in Rural Areas | C15: 10 | D15: 21
A16: 12 | B16: Grassroots Democracy – Part 3 Local Government in Urban Areas | C16: 7 | D16: 15
... A18: 14 | B18: Chapter 14: Economic Activities Around Us | C18: 5 | D18: 11
B19: Total | C19: =SUM(C5:C18) -> 113 | D19: =SUM(D5:D18) -> 240
A21: ="Grade VII (stage: middle, NCF annual total: "&'Annual Budget'!$E$24&" periods)" -> Grade VII (stage: middle, NCF annual total: 240 periods)
A22: Ch # | B22: Chapter title | C22: Weight | D22: NCF periods
A23: 1 | B23: Geographical Diversity of India | C23: 8 | D23: 21
A24: 2 | B24: Understanding the Weather | C24: 4 | D24: 11
A25: 3 | B25: Climates of India | C25: 9 | D25: 24
A26: 4 | B26: New Beginnings - Cities and States | C26: 8 | D26: 21
A27: 5 | B27: The Rise of Empires | C27: 8 | D27: 21
A28: 6 | B28: The Age of Reorganisation | C28: 8 | D28: 21
A29: 7 | B29: The Gupta Era - An Age of Tireless Creativity | C29: 8 | D29: 21
A30: 8 | B30: How the Land Becomes Sacred | C30: 7 | D30: 18
A31: 9 | B31: From the Rulers to the Ruled - Types of Governments | C31: 9 | D31: 24
A32: 10 | B32: The Constitution of India - An Introduction | C32: 8 | D32: 21
A33: 11 | B33: From Barter to Money | C33: 6 | D33: 16
A34: 12 | B34: Understanding Markets | C34: 8 | D34: 21
B35: Total | C35: =SUM(C23:C34) -> 91 | D35: =SUM(D23:D34) -> 240
A37: ="Grade VIII (stage: middle, NCF annual total: "&'Annual Budget'!$E$25&" periods)" -> Grade VIII (stage: middle, NCF annual total: 240 periods)
A38: Ch # | B38: Chapter title | C38: Weight | D38: NCF periods
A39: 1 | B39: Chapter 1: Natural Resources and Their Use | C39: 8 | D39: 13
A40: 2 | B40: Chapter 2: Reshaping India's Political Map | C40: 11 | D40: 19
A41: 3 | B41: Chapter 3: The Rise of the Marathas | C41: 12 | D41: 20
A42: 4 | B42: Chapter 4: The Colonial Era in India | C42: 14 | D42: 24
A43: 5 | B43: Chapter 5: Universal Franchise and India's Electoral System | C43: 9 | D43: 15
A44: 6 | B44: Chapter 6: The Parliamentary System: Legislature and Executive | C44: 9 | D44: 15
...

Sheet The World Around Us
A1: The World Around Us — chapter-wise NCF period allocation
A3: ="Grade III (stage: preparatory, NCF annual total: "&'Annual Budget'!$E$26&" periods)" -> Grade III (stage: preparatory, NCF annual total: 300 periods)
A4: Ch # | B4: Chapter title | C4: Weight | D4: NCF periods
A5: 1 | B5: Family and Friends | C5: 6 | D5: 22
A6: 2 | B6: Going to the Mela | C6: 6.5 | D6: 24
A7: 3 | B7: Celebrating Festivals | C7: 6 | D7: 22
A8: 4 | B8: Getting to Know Plants | C8: 7.5 | D8: 28
A9: 5 | B9: Plants and Animals Live Together | C9: 6 | D9: 22
A10: 6 | B10: Living in Harmony | C10: 9.5 | D10: 35
A11: 7 | B11: Water–A Precious Gift | C11: 7.5 | D11: 27
A12: 8 | B12: Food We Eat | C12: 4 | D12: 15
A13: 9 | B13: Staying Healthy and Happy | C13: 3.5 | D13: 13
A14: 10 | B14: This World of Things | C14: 6 | D14: 22
A15: 11 | B15: Making Things | C15: 9.5 | D15: 35
A16: 12 | B16: Taking Charge of Waste | C16: 9.5 | D16: 35
B17: Total | C17: =SUM(C5:C16) -> 81.5 | D17: =SUM(D5:D16) -> 300
A19: ="Grade IV (stage: preparatory, NCF annual total: "&'Annual Budget'!$E$27&" periods)" -> Grade IV (stage: preparatory, NCF annual total: 300 periods)
A20: Ch # | B20: Chapter title | C20: Weight | D20: NCF periods
A21: 1 | B21: Living Together | C21: 6 | D21: 22
A22: 2 | B22: Exploring Our Neighbourhood | C22: 10 | D22: 37
A23: 3 | B23: Nature Trail | C23: 9.5 | D23: 35
A24: 4 | B24: Growing up with Nature | C24: 7.5 | D24: 28
A25: 5 | B25: Food for Health | C25: 7.5 | D25: 27
A26: 6 | B26: Happy and Healthy Living | C26: 11 | D26: 40
A27: 7 | B27: How Things Work | C27: 7.5 | D27: 27
A28: 8 | B28: How Things are Made | C28: 7.5 | D28: 27
A29: 9 | B29: Different Lands, Different Lives | C29: 9.5 | D29: 35
A30: 10 | B30: Our Sky | C30: 6 | D30: 22
B31: Total | C31: =SUM(C21:C30) -> 82 | D31: =SUM(D21:D30) -> 300
A33: ="Grade V (stage: preparatory, NCF annual total: "&'Annual Budget'!$E$28&" periods)" -> Grade V (stage: preparatory, NCF annual total: 300 periods)
A34: Ch # | B34: Chapter title | C34: Weight | D34: NCF periods
A35: 1 | B35: Water — The Essence of Life | C35: 10.5 | D35: 29
A36: 2 | B36: Journey of a River | C36: 12.5 | D36: 35
A37: 3 | B37: The Mystery of Food | C37: 6 | D37: 17
A38: 4 | B38: Our School—A Happy Place | C38: 12.5 | D38: 35
A39: 5 | B39: Our Vibrant Country | C39: 12 | D39: 34
A40: 6 | B40: Some Unique Places | C40: 14.5 | D40: 41
A41: 7 | B41: Energy—How Things Work | C41: 9.5 | D41: 27
A42: 8 | B42: Clothes—How Things are Made | C42: 7.5 | D42: 21
A43: 9 | B43: Rhythms of Nature | C43: 9.5 | D43: 26
...
