Workbook

Sheet Summary
A1: Chapter-wise Period Allocation
A2: Pick a subject and class, then type your annual teaching budget (periods for the year). Aruvi spreads the budget across the chapters by each chapter's effort weight - heavier chapters get more periods.
A4: Subject | B4: The World Around Us | G4: Duration assumption
A5: Class | B5: III | G5: 40 min — classes III–VII
A6: Annual budget | B6: =IF(COUNTIFS(budget!$A:$A,$B$4,budget!$B:$B,$B$5)=0,"",IF(SUMIFS(budget!$C:$C,budget!$A:$A,$B$4,budget!$B:$B,$B$5)=0,"",SUMIFS(budget!$C:$C,budget!$A:$A,$B$4,budget!$B:$B,$B$5))) -> 140 | C6: periods / year | G6: 45 min — class VIII
A7: =IF($B$4="","Choose a subject and class, then enter your annual budget.",IF(COUNTIFS(Chapters!$A:$A,$B$4,Chapters!$B:$B,$B$5)=0,"No chapters found for this subject and class - try another combination.",IF($B$6="","Enter your annual budget (periods) above.",""))) | G7: 50 min — class IX
A9: Ch # | B9: Chapter title | C9: Weight | D9: Periods
A10: =IFERROR(INDEX(Chapters!$C:$C,MATCH($B$4&"|"&$B$5&"|"&(ROW()-9),Chapters!$F:$F,0)),"") -> 1 | B10: =IFERROR(INDEX(Chapters!$D:$D,MATCH($B$4&"|"&$B$5&"|"&(ROW()-9),Chapters!$F:$F,0)),"") -> Family and Friends | C10: =IFERROR(INDEX(Chapters!$E:$E,MATCH($B$4&"|"&$B$5&"|"&(ROW()-9),Chapters!$F:$F,0)),"") -> 6 | D10: =IF(OR($C10="",$C$28=0,$B$6=""),"",ROUND(SUM($C$10:$C10)/$C$28*$B$6,0)-ROUND((SUM($C$10:$C10)-$C10)/$C$28*$B$6,0)) -> 10
A11: =IFERROR(INDEX(Chapters!$C:$C,MATCH($B$4&"|"&$B$5&"|"&(ROW()-9),Chapters!$F:$F,0)),"") -> 2 | B11: =IFERROR(INDEX(Chapters!$D:$D,MATCH($B$4&"|"&$B$5&"|"&(ROW()-9),Chapters!$F:$F,0)),"") -> Going to the Mela | C11: =IFERROR(INDEX(Chapters!$E:$E,MATCH($B$4&"|"&$B$5&"|"&(ROW()-9),Chapters!$F:$F,0)),"") -> 6.5 | D11: =IF(OR($C11="",$C$28=0,$B$6=""),"",ROUND(SUM($C$10:$C11)/$C$28*$B$6,0)-ROUND((SUM($C$10:$C11)-$C11)/$C$28*$B$6,0)) -> 11
A12: =IFERROR(INDEX(Chapters!$C:$C,MATCH($B$4&"|"&$B$5&"|"&(ROW()-9),Chapters!$F:$F,0)),"") -> 3 | B12: =IFERROR(INDEX(Chapters!$D:$D,MATCH($B$4&"|"&$B$5&"|"&(ROW()-9),Chapters!$F:$F,0)),"") -> Celebrating Festivals | C12: =IFERROR(INDEX(Chapters!$E:$E,MATCH($B$4&"|"&$B$5&"|"&(ROW()-9),Chapters!$F:$F,0)),"") -> 6 | D12: =IF(OR($C12="",$C$28=0,$B$6=""),"",ROUND(SUM($C$10:$C12)/$C$28*$B$6,0)-ROUND((SUM($C$10:$C12)-$C12)/$C$28*$B$6,0)) -> 11
A13: =IFERROR(INDEX(Chapters!$C:$C,MATCH($B$4&"|"&$B$5&"|"&(ROW()-9),Chapters!$F:$F,0)),"") -> 4 | B13: =IFERROR(INDEX(Chapters!$D:$D,MATCH($B$4&"|"&$B$5&"|"&(ROW()-9),Chapters!$F:$F,0)),"") -> Getting to Know Plants | C13: =IFERROR(INDEX(Chapters!$E:$E,MATCH($B$4&"|"&$B$5&"|"&(ROW()-9),Chapters!$F:$F,0)),"") -> 7.5 | D13: =IF(OR($C13="",$C$28=0,$B$6=""),"",ROUND(SUM($C$10:$C13)/$C$28*$B$6,0)-ROUND((SUM($C$10:$C13)-$C13)/$C$28*$B$6,0)) -> 13
A14: =IFERROR(INDEX(Chapters!$C:$C,MATCH($B$4&"|"&$B$5&"|"&(ROW()-9),Chapters!$F:$F,0)),"") -> 5 | B14: =IFERROR(INDEX(Chapters!$D:$D,MATCH($B$4&"|"&$B$5&"|"&(ROW()-9),Chapters!$F:$F,0)),"") -> Plants and Animals Live Together | C14: =IFERROR(INDEX(Chapters!$E:$E,MATCH($B$4&"|"&$B$5&"|"&(ROW()-9),Chapters!$F:$F,0)),"") -> 6 | D14: =IF(OR($C14="",$C$28=0,$B$6=""),"",ROUND(SUM($C$10:$C14)/$C$28*$B$6,0)-ROUND((SUM($C$10:$C14)-$C14)/$C$28*$B$6,0)) -> 10
A15: =IFERROR(INDEX(Chapters!$C:$C,MATCH($B$4&"|"&$B$5&"|"&(ROW()-9),Chapters!$F:$F,0)),"") -> 6 | B15: =IFERROR(INDEX(Chapters!$D:$D,MATCH($B$4&"|"&$B$5&"|"&(ROW()-9),Chapters!$F:$F,0)),"") -> Living in Harmony | C15: =IFERROR(INDEX(Chapters!$E:$E,MATCH($B$4&"|"&$B$5&"|"&(ROW()-9),Chapters!$F:$F,0)),"") -> 9.5 | D15: =IF(OR($C15="",$C$28=0,$B$6=""),"",ROUND(SUM($C$10:$C15)/$C$28*$B$6,0)-ROUND((SUM($C$10:$C15)-$C15)/$C$28*$B$6,0)) -> 16
A16: =IFERROR(INDEX(Chapters!$C:$C,MATCH($B$4&"|"&$B$5&"|"&(ROW()-9),Chapters!$F:$F,0)),"") -> 7 | B16: =IFERROR(INDEX(Chapters!$D:$D,MATCH($B$4&"|"&$B$5&"|"&(ROW()-9),Chapters!$F:$F,0)),"") -> Water–A Precious Gift | C16: =IFERROR(INDEX(Chapters!$E:$E,MATCH($B$4&"|"&$B$5&"|"&(ROW()-9),Chapters!$F:$F,0)),"") -> 7.5 | D16: =IF(OR($C16="",$C$28=0,$B$6=""),"",ROUND(SUM($C$10:$C16)/$C$28*$B$6,0)-ROUND((SUM($C$10:$C16)-$C16)/$C$28*$B$6,0)) -> 13
A17: =IFERROR(INDEX(Chapters!$C:$C,MATCH($B$4&"|"&$B$5&"|"&(ROW()-9),Chapters!$F:$F,0)),"") -> 8 | B17: =IFERROR(INDEX(Chapters!$D:$D,MATCH($B$4&"|"&$B$5&"|"&(ROW()-9),Chapters!$F:$F,0)),"") -> Food We Eat | C17: =IFERROR(INDEX(Chapters!$E:$E,MATCH($B$4&"|"&$B$5&"|"&(ROW()-9),Chapters!$F:$F,0)),"") -> 4 | D17: =IF(OR($C17="",$C$28=0,$B$6=""),"",ROUND(SUM($C$10:$C17)/$C$28*$B$6,0)-ROUND((SUM($C$10:$C17)-$C17)/$C$28*$B$6,0)) -> 7
A18: =IFERROR(INDEX(Chapters!$C:$C,MATCH($B$4&"|"&$B$5&"|"&(ROW()-9),Chapters!$F:$F,0)),"") -> 9 | B18: =IFERROR(INDEX(Chapters!$D:$D,MATCH($B$4&"|"&$B$5&"|"&(ROW()-9),Chapters!$F:$F,0)),"") -> Staying Healthy and Happy | C18: =IFERROR(INDEX(Chapters!$E:$E,MATCH($B$4&"|"&$B$5&"|"&(ROW()-9),Chapters!$F:$F,0)),"") -> 3.5 | D18: =IF(OR($C18="",$C$28=0,$B$6=""),"",ROUND(SUM($C$10:$C18)/$C$28*$B$6,0)-ROUND((SUM($C$10:$C18)-$C18)/$C$28*$B$6,0)) -> 6
A19: =IFERROR(INDEX(Chapters!$C:$C,MATCH($B$4&"|"&$B$5&"|"&(ROW()-9),Chapters!$F:$F,0)),"") -> 10 | B19: =IFERROR(INDEX(Chapters!$D:$D,MATCH($B$4&"|"&$B$5&"|"&(ROW()-9),Chapters!$F:$F,0)),"") -> This World of Things | C19: =IFERROR(INDEX(Chapters!$E:$E,MATCH($B$4&"|"&$B$5&"|"&(ROW()-9),Chapters!$F:$F,0)),"") -> 6 | D19: =IF(OR($C19="",$C$28=0,$B$6=""),"",ROUND(SUM($C$10:$C19)/$C$28*$B$6,0)-ROUND((SUM($C$10:$C19)-$C19)/$C$28*$B$6,0)) -> 10
A20: =IFERROR(INDEX(Chapters!$C:$C,MATCH($B$4&"|"&$B$5&"|"&(ROW()-9),Chapters!$F:$F,0)),"") -> 11 | B20: =IFERROR(INDEX(Chapters!$D:$D,MATCH($B$4&"|"&$B$5&"|"&(ROW()-9),Chapters!$F:$F,0)),"") -> Making Things | C20: =IFERROR(INDEX(Chapters!$E:$E,MATCH($B$4&"|"&$B$5&"|"&(ROW()-9),Chapters!$F:$F,0)),"") -> 9.5 | D20: =IF(OR($C20="",$C$28=0,$B$6=""),"",ROUND(SUM($C$10:$C20)/$C$28*$B$6,0)-ROUND((SUM($C$10:$C20)-$C20)/$C$28*$B$6,0)) -> 17
A21: =IFERROR(INDEX(Chapters!$C:$C,MATCH($B$4&"|"&$B$5&"|"&(ROW()-9),Chapters!$F:$F,0)),"") -> 12 | B21: =IFERROR(INDEX(Chapters!$D:$D,MATCH($B$4&"|"&$B$5&"|"&(ROW()-9),Chapters!$F:$F,0)),"") -> Taking Charge of Waste | C21: =IFERROR(INDEX(Chapters!$E:$E,MATCH($B$4&"|"&$B$5&"|"&(ROW()-9),Chapters!$F:$F,0)),"") -> 9.5 | D21: =IF(OR($C21="",$C$28=0,$B$6=""),"",ROUND(SUM($C$10:$C21)/$C$28*$B$6,0)-ROUND((SUM($C$10:$C21)-$C21)/$C$28*$B$6,0)) -> 16
... A27: =IFERROR(INDEX(Chapters!$C:$C,MATCH($B$4&"|"&$B$5&"|"&(ROW()-9),Chapters!$F:$F,0)),"") | B27: =IFERROR(INDEX(Chapters!$D:$D,MATCH($B$4&"|"&$B$5&"|"&(ROW()-9),Chapters!$F:$F,0)),"") | C27: =IFERROR(INDEX(Chapters!$E:$E,MATCH($B$4&"|"&$B$5&"|"&(ROW()-9),Chapters!$F:$F,0)),"") | D27: =IF(OR($C27="",$C$28=0,$B$6=""),"",ROUND(SUM($C$10:$C27)/$C$28*$B$6,0)-ROUND((SUM($C$10:$C27)-$C27)/$C$28*$B$6,0))
B28: Total | C28: =SUM(C10:C27) -> 81.5 | D28: =SUM(D10:D27) -> 140

Sheet Chapters
A1: Subject | B1: Class | C1: Ch # | D1: Chapter title | E1: Weight | F1: Key | G1: Within #
A2: English | B2: III | C2: 1 | D2: Fun with Friends (Fun with Friends) | E2: 5.5 | F2: English|III|1 | G2: 1
A3: English | B3: III | C3: 2 | D3: Colours (Fun with Friends) | E3: 6.5 | F3: English|III|2 | G3: 2
A4: English | B4: III | C4: 3 | D4: Badal and Moti (Badal and Moti) | E4: 11.5 | F4: English|III|3 | G4: 3
A5: English | B5: III | C5: 4 | D5: Best Friends (Best Friends) | E5: 10 | F5: English|III|4 | G5: 4
A6: English | B6: III | C6: 5 | D6: What do You do? (Best Friends) | E6: 3.5 | F6: English|III|5 | G6: 5
A7: English | B7: III | C7: 6 | D7: Toys and Games (Picture Reading) (Toys and Games) | E7: 5.5 | F7: English|III|6 | G7: 6
A8: English | B8: III | C8: 7 | D8: Out in the Garden (Toys and Games) | E8: 6.5 | F8: English|III|7 | G8: 7
A9: English | B9: III | C9: 8 | D9: Talking Toys (Talking Toys) | E9: 10 | F9: English|III|8 | G9: 8
A10: English | B10: III | C10: 9 | D10: Paper Boats (Paper Boats) | E10: 8.5 | F10: English|III|9 | G10: 9
A11: English | B11: III | C11: 10 | D11: Good Food — Picture Reading (The Big Laddoo) | E11: 3.5 | F11: English|III|10 | G11: 10
A12: English | B12: III | C12: 11 | D12: The Big Laddoo (The Big Laddoo) | E12: 11.5 | F12: English|III|11 | G12: 11
A13: English | B13: III | C13: 12 | D13: Thank God! (Thank God!) | E13: 8.5 | F13: English|III|12 | G13: 12
... A341: The World Around Us | B341: V | C341: 10 | D341: Earth—Our Shared Home | E341: 12.5 | F341: The World Around Us|V|10 | G341: 10

Sheet budget
A1: Subject | B1: Class | C1: Annual budget
A2: English | B2: IX | C2: 160
A3: Mathematics | B3: IX | C3: 210
A4: Science | B4: IX | C4: 210
A5: The World Around Us | B5: IX
A6: Social Sciences | B6: IX | C6: 245
A7: English | B7: VI | C7: 140
A8: Mathematics | B8: VI | C8: 180
A9: Science | B9: VI | C9: 180
A10: The World Around Us | B10: VI
A11: Social Sciences | B11: VI | C11: 210
A12: English | B12: III | C12: 140
A13: Mathematics | B13: III | C13: 160
A14: Science | B14: III
A15: The World Around Us | B15: III | C15: 140
A16: Social Sciences | B16: III
A17: English | B17: X | C17: 160
A18: Mathematics | B18: X | C18: 210
A19: Science | B19: X | C19: 210
A20: The World Around Us | B20: X
A21: Social Sciences | B21: X | C21: 245
A22: English | B22: VII | C22: 140
A23: Mathematics | B23: VII | C23: 180
A24: Science | B24: VII | C24: 180
A25: The World Around Us | B25: VII
A26: Social Sciences | B26: VII | C26: 210
A27: English | B27: IV | C27: 140
A28: Mathematics | B28: IV | C28: 160
A29: Science | B29: IV
A30: The World Around Us | B30: IV | C30: 140
A31: Social Sciences | B31: IV
A32: English | B32: V | C32: 140
A33: Mathematics | B33: V | C33: 160
A34: Science | B34: V
A35: The World Around Us | B35: V | C35: 140
A36: Social Sciences | B36: V
A37: English | B37: VIII | C37: 140
A38: Mathematics | B38: VIII | C38: 180
A39: Science | B39: VIII | C39: 180
A40: The World Around Us | B40: VIII
...
